Workbook

Sheet Dados
A1: ID | B1: Sexo: | C1: Idade (anos): | D1: Peso (kg): | E1: Altura (m): | F1: Curso: | G1: Período: | H1: Turno de estudo: | I1: Faz alguma atividade extraclasse. se sim qual (is)? | J1: Se escolheu 'Outros' na questão de número 8. especifique aqui: | K1: Cidade/procedência: | L1: Estado: | M1: Com quem mora: | N1: Se escolheu 'Outros' na questão de número 12. especifique aqui: | O1: Pais participam da vida escolar? | P1: 1- Com que frequência você usa seu celular na vida diária? | Q1: Pontos 1 | R1: 2- Quantas vezes você não pode sair sem levar o celular? | S1: Pontos 2 | T1: 3- Com que frequência você volta se esquecer de levar o celular? | U1: Pontos 3 | V1: 4- Com que frequência você acessa a internet no celular? | W1: Pontos – 4 | X1: 5- Quantas vezes você se sente ansioso quando percebe que está sem o celular? | Y1: Pontos 5 | Z1: 6- Quantas vezes você se sente triste ou deprimido quando é desconectado da Internet ou das redes sociais através do seu celular? | AA1: Pontos 6 | AB1: 7- Quantas vezes você se sente nervoso por não ter o celular com você para se comunicar? | AC1: Pontos 7 | AD1: 8- Quantas vezes você tem medo de sair sem o celular e se sentir doente na rua sem os meios para pedir ajuda imediata ou fazer contato com alguém em quem confia? | AE1: Pontos 8 | AF1: 9- Com que frequência você mantém o celular à mão? | AG1: Pontos 9 | AH1: 10- Com que frequência você mantém o celular ligado 24 horas por dia? | AI1: Pontos 10 | AJ1: 11- Com que frequência você dorme com o celular ligado? | AK1: Pontos 11 | AL1: 12- Com que frequência você acessa o celular mais de 30 vezes por dia para visualizar mensagens. e-mails etc.? | AM1: Pontos 12 | AN1: 13- Com que frequência você se mantém conectado ao celular quando está com amigos ou família? | AO1: Pontos 13 | AP1: 14- Com que frequência você se sente sozinho se não participa de redes sociais ou quando não está em grupo enquanto outros estão? | AQ1: Pontos 14 | AR1: 15- Quantas vezes você mantém na agenda do celular o número de um médico. psicólogo ou hospital por medo de se sentir mal na rua? | AS1: Pontos 15 | AT1: 16- Com que frequência você toca no celular? | AU1: Pontos 16 | AV1: Pontuação final | AW1: Classificação
A2: 2 | B2: Masculino | C2: 18 | D2: 73 | E2: 1.84 | F2: Engenharia de Computação | G2: P3 | H2: Integral | I2: Iniciação Científica ; | K2: Três Corações | L2: Minas Gerais | M2: Amigos/colegas | O2: Às vezes | P2: Sempre | Q2: 2 | R2: Sempre | S2: 2 | T2: Nunca / Raramente | U2: 0 | V2: Sempre | W2: 2 | X2: Nunca / Raramente | Y2: 0 | Z2: Nunca / Raramente | AA2: 0 | AB2: Nunca / Raramente | AC2: 0 | AD2: Frequentemente | AE2: 1 | AF2: Frequentemente | AG2: 1 | AH2: Sempre | AI2: 2 | AJ2: Sempre | AK2: 2 | AL2: Sempre | AM2: 2 | AN2: Frequentemente | AO2: 1 | AP2: Nunca / Raramente | AQ2: 0 | AR2: Frequentemente | AS2: 1 | AT2: Sempre | AU2: 2 | AV2: =SUM(Q2,S2,U2,W2,Y2,AA2,AC2,AE2,AG2,AI2,AK2,AM2,AO2,AQ2,AS2,AU2) -> 18 | AW2: =IF(Table1[[#This Row],[Pontuação final]]<=2,"Nenhum", IF(Table1[[#This Row],[Pontuação final]]<=12,"Leve", IF(Table1[[#This Row],[Pontuação final]]<=22,"Moderado", "Grave"))) -> Moderado
A3: 3 | B3: Masculino | C3: 18 | D3: 75 | E3: 1.75 | F3: Engenharia de Software | G3: P3 | H3: Integral | I3: Outros; | K3: Pouso Alegre | L3: Minas Gerais | M3: Familiares | O3: Sempre | P3: Sempre | Q3: 2 | R3: Nunca / Raramente | S3: 0 | T3: Nunca / Raramente | U3: 0 | V3: Sempre | W3: 2 | X3: Nunca / Raramente | Y3: 0 | Z3: Frequentemente | AA3: 1 | AB3: Sempre | AC3: 2 | AD3: Nunca / Raramente | AE3: 0 | AF3: Frequentemente | AG3: 1 | AH3: Frequentemente | AI3: 1 | AJ3: Frequentemente | AK3: 1 | AL3: Sempre | AM3: 2 | AN3: Frequentemente | AO3: 1 | AP3: Frequentemente | AQ3: 1 | AR3: Sempre | AS3: 2 | AT3: Sempre | AU3: 2 | AV3: =SUM(Q3,S3,U3,W3,Y3,AA3,AC3,AE3,AG3,AI3,AK3,AM3,AO3,AQ3,AS3,AU3) -> 18 | AW3: =IF(Table1[[#This Row],[Pontuação final]]<=2,"Nenhum", IF(Table1[[#This Row],[Pontuação final]]<=12,"Leve", IF(Table1[[#This Row],[Pontuação final]]<=22,"Moderado", "Grave"))) -> Moderado
A4: 4 | B4: Feminino | C4: 22 | D4: 67 | E4: 1.73 | F4: Engenharia de Software | G4: P9 | H4: Noturno | I4: Monitoria ;Estágio ; | K4: Santa Rita do Sapucaí | L4: Minas Gerais | M4: Familiares | O4: Às vezes | P4: Sempre | Q4: 2 | R4: Nunca / Raramente | S4: 0 | T4: Nunca / Raramente | U4: 0 | V4: Sempre | W4: 2 | X4: Nunca / Raramente | Y4: 0 | Z4: Nunca / Raramente | AA4: 0 | AB4: Frequentemente | AC4: 1 | AD4: Frequentemente | AE4: 1 | AF4: Frequentemente | AG4: 1 | AH4: Sempre | AI4: 2 | AJ4: Sempre | AK4: 2 | AL4: Nunca / Raramente | AM4: 0 | AN4: Frequentemente | AO4: 1 | AP4: Nunca / Raramente | AQ4: 0 | AR4: Frequentemente | AS4: 1 | AT4: Nunca / Raramente | AU4: 0 | AV4: =SUM(Q4,S4,U4,W4,Y4,AA4,AC4,AE4,AG4,AI4,AK4,AM4,AO4,AQ4,AS4,AU4) -> 13 | AW4: =IF(Table1[[#This Row],[Pontuação final]]<=2,"Nenhum", IF(Table1[[#This Row],[Pontuação final]]<=12,"Leve", IF(Table1[[#This Row],[Pontuação final]]<=22,"Moderado", "Grave"))) -> Moderado
A5: 5 | B5: Masculino | C5: 20 | D5: 85 | E5: 1.82 | F5: Engenharia de Computação | G5: P6 | H5: Integral | I5: Trabalho ; | K5: Atibaia | L5: São Paulo | M5: Sozinho | O5: Às vezes | P5: Frequentemente | Q5: 1 | R5: Nunca / Raramente | S5: 0 | T5: Nunca / Raramente | U5: 0 | V5: Frequentemente | W5: 1 | X5: Nunca / Raramente | Y5: 0 | Z5: Nunca / Raramente | AA5: 0 | AB5: Nunca / Raramente | AC5: 0 | AD5: Nunca / Raramente | AE5: 0 | AF5: Frequentemente | AG5: 1 | AH5: Nunca / Raramente | AI5: 0 | AJ5: Nunca / Raramente | AK5: 0 | AL5: Frequentemente | AM5: 1 | AN5: Nunca / Raramente | AO5: 0 | AP5: Nunca / Raramente | AQ5: 0 | AR5: Nunca / Raramente | AS5: 0 | AT5: Frequentemente | AU5: 1 | AV5: =SUM(Q5,S5,U5,W5,Y5,AA5,AC5,AE5,AG5,AI5,AK5,AM5,AO5,AQ5,AS5,AU5) -> 5 | AW5: =IF(Table1[[#This Row],[Pontuação final]]<=2,"Nenhum", IF(Table1[[#This Row],[Pontuação final]]<=12,"Leve", IF(Table1[[#This Row],[Pontuação final]]<=22,"Moderado", "Grave"))) -> Leve
A6: 6 | B6: Masculino | C6: 19 | D6: 64 | E6: 1.9 | F6: Engenharia de Telecomunicações | G6: P5 | H6: Integral | I6: Iniciação Científica ; | K6: Lambari | L6: Minas Gerais | M6: Sozinho | O6: Sempre | P6: Sempre | Q6: 2 | R6: Nunca / Raramente | S6: 0 | T6: Nunca / Raramente | U6: 0 | V6: Sempre | W6: 2 | X6: Nunca / Raramente | Y6: 0 | Z6: Nunca / Raramente | AA6: 0 | AB6: Nunca / Raramente | AC6: 0 | AD6: Nunca / Raramente | AE6: 0 | AF6: Frequentemente | AG6: 1 | AH6: Frequentemente | AI6: 1 | AJ6: Sempre | AK6: 2 | AL6: Frequentemente | AM6: 1 | AN6: Nunca / Raramente | AO6: 0 | AP6: Nunca / Raramente | AQ6: 0 | AR6: Nunca / Raramente | AS6: 0 | AT6: Frequentemente | AU6: 1 | AV6: =SUM(Q6,S6,U6,W6,Y6,AA6,AC6,AE6,AG6,AI6,AK6,AM6,AO6,AQ6,AS6,AU6) -> 10 | AW6: =IF(Table1[[#This Row],[Pontuação final]]<=2,"Nenhum", IF(Table1[[#This Row],[Pontuação final]]<=12,"Leve", IF(Table1[[#This Row],[Pontuação final]]<=22,"Moderado", "Grave"))) -> Leve
A7: 7 | B7: Masculino | C7: 19 | D7: 95 | E7: 1.92 | F7: Engenharia de Software | G7: P1 | H7: Integral | I7: Estágio ; | K7: Santa Rita do Sapucaí | L7: Minas Gerais | M7: Familiares | O7: Às vezes | P7: Sempre | Q7: 2 | R7: Frequentemente | S7: 1 | T7: Frequentemente | U7: 1 | V7: Sempre | W7: 2 | X7: Frequentemente | Y7: 1 | Z7: Nunca / Raramente | AA7: 0 | AB7: Frequentemente | AC7: 1 | AD7: Nunca / Raramente | AE7: 0 | AF7: Frequentemente | AG7: 1 | AH7: Sempre | AI7: 2 | AJ7: Nunca / Raramente | AK7: 0 | AL7: Frequentemente | AM7: 1 | AN7: Frequentemente | AO7: 1 | AP7: Frequentemente | AQ7: 1 | AR7: Nunca / Raramente | AS7: 0 | AT7: Sempre | AU7: 2 | AV7: =SUM(Q7,S7,U7,W7,Y7,AA7,AC7,AE7,AG7,AI7,AK7,AM7,AO7,AQ7,AS7,AU7) -> 16 | AW7: =IF(Table1[[#This Row],[Pontuação final]]<=2,"Nenhum", IF(Table1[[#This Row],[Pontuação final]]<=12,"Leve", IF(Table1[[#This Row],[Pontuação final]]<=22,"Moderado", "Grave"))) -> Moderado
A8: 8 | B8: Masculino | C8: 19 | D8: 56 | E8: 1.7 | F8: Engenharia de Telecomunicações | G8: P3 | H8: Integral | I8: Iniciação Científica ;Monitoria ; | K8: Pouso Alegre | L8: Minas Gerais | M8: Amigos/colegas | O8: Nunca | P8: Sempre | Q8: 2 | R8: Sempre | S8: 2 | T8: Sempre | U8: 2 | V8: Frequentemente | W8: 1 | X8: Nunca / Raramente | Y8: 0 | Z8: Nunca / Raramente | AA8: 0 | AB8: Nunca / Raramente | AC8: 0 | AD8: Nunca / Raramente | AE8: 0 | AF8: Frequentemente | AG8: 1 | AH8: Frequentemente | AI8: 1 | AJ8: Sempre | AK8: 2 | AL8: Sempre | AM8: 2 | AN8: Nunca / Raramente | AO8: 0 | AP8: Nunca / Raramente | AQ8: 0 | AR8: Nunca / Raramente | AS8: 0 | AT8: Sempre | AU8: 2 | AV8: =SUM(Q8,S8,U8,W8,Y8,AA8,AC8,AE8,AG8,AI8,AK8,AM8,AO8,AQ8,AS8,AU8) -> 15 | AW8: =IF(Table1[[#This Row],[Pontuação final]]<=2,"Nenhum", IF(Table1[[#This Row],[Pontuação final]]<=12,"Leve", IF(Table1[[#This Row],[Pontuação final]]<=22,"Moderado", "Grave"))) -> Moderado
A9: 9 | B9: Feminino | C9: 20 | D9: 85 | E9: 1.66 | F9: Engenharia de Software | G9: P4 | H9: Integral | I9: Outros; | J9: Casa Viva | K9: Santa Rita do Sapucaí | L9: Minas Gerais | M9: Familiares | O9: Sempre | P9: Sempre | Q9: 2 | R9: Frequentemente | S9: 1 | T9: Nunca / Raramente | U9: 0 | V9: Sempre | W9: 2 | X9: Frequentemente | Y9: 1 | Z9: Nunca / Raramente | AA9: 0 | AB9: Frequentemente | AC9: 1 | AD9: Frequentemente | AE9: 1 | AF9: Frequentemente | AG9: 1 | AH9: Nunca / Raramente | AI9: 0 | AJ9: Nunca / Raramente | AK9: 0 | AL9: Sempre | AM9: 2 | AN9: Frequentemente | AO9: 1 | AP9: Nunca / Raramente | AQ9: 0 | AR9: Nunca / Raramente | AS9: 0 | AT9: Sempre | AU9: 2 | AV9: =SUM(Q9,S9,U9,W9,Y9,AA9,AC9,AE9,AG9,AI9,AK9,AM9,AO9,AQ9,AS9,AU9) -> 14 | AW9: =IF(Table1[[#This Row],[Pontuação final]]<=2,"Nenhum", IF(Table1[[#This Row],[Pontuação final]]<=12,"Leve", IF(Table1[[#This Row],[Pontuação final]]<=22,"Moderado", "Grave"))) -> Moderado
A10: 10 | B10: Feminino | C10: 21 | D10: 66 | E10: 1.62 | F10: Engenharia de Computação | G10: P9 | H10: Integral | I10: Trabalho ; | K10: São Paulo | L10: São Paulo | M10: Familiares | O10: Sempre | P10: Sempre | Q10: 2 | R10: Sempre | S10: 2 | T10: Nunca / Raramente | U10: 0 | V10: Sempre | W10: 2 | X10: Frequentemente | Y10: 1 | Z10: Sempre | AA10: 2 | AB10: Sempre | AC10: 2 | AD10: Sempre | AE10: 2 | AF10: Frequentemente | AG10: 1 | AH10: Sempre | AI10: 2 | AJ10: Frequentemente | AK10: 1 | AL10: Frequentemente | AM10: 1 | AN10: Frequentemente | AO10: 1 | AP10: Frequentemente | AQ10: 1 | AR10: Nunca / Raramente | AS10: 0 | AT10: Frequentemente | AU10: 1 | AV10: =SUM(Q10,S10,U10,W10,Y10,AA10,AC10,AE10,AG10,AI10,AK10,AM10,AO10,AQ10,AS10,AU10) -> 21 | AW10: =IF(Table1[[#This Row],[Pontuação final]]<=2,"Nenhum", IF(Table1[[#This Row],[Pontuação final]]<=12,"Leve", IF(Table1[[#This Row],[Pontuação final]]<=22,"Moderado", "Grave"))) -> Moderado
A11: 11 | B11: Masculino | C11: 20 | D11: 58 | E11: 1.71 | F11: Engenharia de Computação | G11: P2 | H11: Integral | I11: Estágio ; | K11: Natércia | L11: Minas Gerais | M11: Amigos/colegas | O11: Nunca | P11: Sempre | Q11: 2 | R11: Nunca / Raramente | S11: 0 | T11: Sempre | U11: 2 | V11: Sempre | W11: 2 | X11: Frequentemente | Y11: 1 | Z11: Frequentemente | AA11: 1 | AB11: Frequentemente | AC11: 1 | AD11: Nunca / Raramente | AE11: 0 | AF11: Frequentemente | AG11: 1 | AH11: Sempre | AI11: 2 | AJ11: Nunca / Raramente | AK11: 0 | AL11: Sempre | AM11: 2 | AN11: Frequentemente | AO11: 1 | AP11: Nunca / Raramente | AQ11: 0 | AR11: Nunca / Raramente | AS11: 0 | AT11: Sempre | AU11: 2 | AV11: =SUM(Q11,S11,U11,W11,Y11,AA11,AC11,AE11,AG11,AI11,AK11,AM11,AO11,AQ11,AS11,AU11) -> 17 | AW11: =IF(Table1[[#This Row],[Pontuação final]]<=2,"Nenhum", IF(Table1[[#This Row],[Pontuação final]]<=12,"Leve", IF(Table1[[#This Row],[Pontuação final]]<=22,"Moderado", "Grave"))) -> Moderado
A12: 12 | B12: Feminino | C12: 29 | D12: 75 | E12: 1.69 | F12: Engenharia de Telecomunicações | G12: P6 | H12: Noturno | I12: Iniciação Científica ;Estágio ;Trabalho ; | K12: São Lourenço | L12: Minas Gerais | M12: Sozinho | O12: Nunca | P12: Sempre | Q12: 2 | R12: Nunca / Raramente | S12: 0 | T12: Sempre | U12: 2 | V12: Sempre | W12: 2 | X12: Sempre | Y12: 2 | Z12: Sempre | AA12: 2 | AB12: Sempre | AC12: 2 | AD12: Sempre | AE12: 2 | AF12: Sempre | AG12: 2 | AH12: Sempre | AI12: 2 | AJ12: Sempre | AK12: 2 | AL12: Sempre | AM12: 2 | AN12: Sempre | AO12: 2 | AP12: Sempre | AQ12: 2 | AR12: Frequentemente | AS12: 1 | AT12: Sempre | AU12: 2 | AV12: =SUM(Q12,S12,U12,W12,Y12,AA12,AC12,AE12,AG12,AI12,AK12,AM12,AO12,AQ12,AS12,AU12) -> 29 | AW12: =IF(Table1[[#This Row],[Pontuação final]]<=2,"Nenhum", IF(Table1[[#This Row],[Pontuação final]]<=12,"Leve", IF(Table1[[#This Row],[Pontuação final]]<=22,"Moderado", "Grave"))) -> Grave
A13: 13 | B13: Masculino | C13: 21 | D13: 68 | E13: 1.8 | F13: Engenharia de Computação | G13: P6 | H13: Noturno | I13: Iniciação Científica ; | K13: Cachoeira de Minas | L13: Minas Gerais | M13: Familiares | O13: Às vezes | P13: Sempre | Q13: 2 | R13: Sempre | S13: 2 | T13: Sempre | U13: 2 | V13: Sempre | W13: 2 | X13: Frequentemente | Y13: 1 | Z13: Nunca / Raramente | AA13: 0 | AB13: Frequentemente | AC13: 1 | AD13: Sempre | AE13: 2 | AF13: Frequentemente | AG13: 1 | AH13: Sempre | AI13: 2 | AJ13: Sempre | AK13: 2 | AL13: Sempre | AM13: 2 | AN13: Frequentemente | AO13: 1 | AP13: Frequentemente | AQ13: 1 | AR13: Nunca / Raramente | AS13: 0 | AT13: Sempre | AU13: 2 | AV13: =SUM(Q13,S13,U13,W13,Y13,AA13,AC13,AE13,AG13,AI13,AK13,AM13,AO13,AQ13,AS13,AU13) -> 23 | AW13: =IF(Table1[[#This Row],[Pontuação final]]<=2,"Nenhum", IF(Table1[[#This Row],[Pontuação final]]<=12,"Leve", IF(Table1[[#This Row],[Pontuação final]]<=22,"Moderado", "Grave"))) -> Grave
A14: 14 | B14: Feminino | C14: 24 | D14: 75 | E14: 1.62 | F14: Engenharia de Software | G14: P7 | H14: Noturno | I14: Trabalho ; | K14: Pouso Alegre | L14: Minas Gerais | M14: Outros | N14: Namorado | O14: Às vezes | P14: Sempre | Q14: 2 | R14: Sempre | S14: 2 | T14: Frequentemente | U14: 1 | V14: Sempre | W14: 2 | X14: Nunca / Raramente | Y14: 0 | Z14: Nunca / Raramente | AA14: 0 | AB14: Nunca / Raramente | AC14: 0 | AD14: Sempre | AE14: 2 | AF14: Frequentemente | AG14: 1 | AH14: Frequentemente | AI14: 1 | AJ14: Nunca / Raramente | AK14: 0 | AL14: Frequentemente | AM14: 1 | AN14: Nunca / Raramente | AO14: 0 | AP14: Nunca / Raramente | AQ14: 0 | AR14: Sempre | AS14: 2 | AT14: Frequentemente | AU14: 1 | AV14: =SUM(Q14,S14,U14,W14,Y14,AA14,AC14,AE14,AG14,AI14,AK14,AM14,AO14,AQ14,AS14,AU14) -> 15 | AW14: =IF(Table1[[#This Row],[Pontuação final]]<=2,"Nenhum", IF(Table1[[#This Row],[Pontuação final]]<=12,"Leve", IF(Table1[[#This Row],[Pontuação final]]<=22,"Moderado", "Grave"))) -> Moderado
A15: 15 | B15: Masculino | C15: 19 | D15: 82 | E15: 1.75 | F15: Engenharia de Controle e Automação | G15: P3 | H15: Integral | I15: Iniciação Científica ; | K15: Machado | L15: Minas Gerais | M15: Amigos/colegas | O15: Sempre | P15: Frequentemente | Q15: 1 | R15: Sempre | S15: 2 | T15: Sempre | U15: 2 | V15: Sempre | W15: 2 | X15: Frequentemente | Y15: 1 | Z15: Frequentemente | AA15: 1 | AB15: Sempre | AC15: 2 | AD15: Sempre | AE15: 2 | AF15: Frequentemente | AG15: 1 | AH15: Sempre | AI15: 2 | AJ15: Sempre | AK15: 2 | AL15: Nunca / Raramente | AM15: 0 | AN15: Frequentemente | AO15: 1 | AP15: Nunca / Raramente | AQ15: 0 | AR15: Frequentemente | AS15: 1 | AT15: Frequentemente | AU15: 1 | AV15: =SUM(Q15,S15,U15,W15,Y15,AA15,AC15,AE15,AG15,AI15,AK15,AM15,AO15,AQ15,AS15,AU15) -> 21 | AW15: =IF(Table1[[#This Row],[Pontuação final]]<=2,"Nenhum", IF(Table1[[#This Row],[Pontuação final]]<=12,"Leve", IF(Table1[[#This Row],[Pontuação final]]<=22,"Moderado", "Grave"))) -> Moderado
A16: 16 | B16: Masculino | C16: 18 | D16: 89 | E16: 1.73 | F16: Engenharia de Software | G16: P1 | H16: Integral | I16: Outros; | K16: Eloi Mendes | L16: Minas Gerais | M16: Sozinho | O16: Sempre | P16: Sempre | Q16: 2 | R16: Frequentemente | S16: 1 | T16: Frequentemente | U16: 1 | V16: Sempre | W16: 2 | X16: Frequentemente | Y16: 1 | Z16: Frequentemente | AA16: 1 | AB16: Frequentemente | AC16: 1 | AD16: Sempre | AE16: 2 | AF16: Frequentemente | AG16: 1 | AH16: Nunca / Raramente | AI16: 0 | AJ16: Frequentemente | AK16: 1 | AL16: Sempre | AM16: 2 | AN16: Frequentemente | AO16: 1 | AP16: Frequentemente | AQ16: 1 | AR16: Nunca / Raramente | AS16: 0 | AT16: Sempre | AU16: 2 | AV16: =SUM(Q16,S16,U16,W16,Y16,AA16,AC16,AE16,AG16,AI16,AK16,AM16,AO16,AQ16,AS16,AU16) -> 19 | AW16: =IF(Table1[[#This Row],[Pontuação final]]<=2,"Nenhum", IF(Table1[[#This Row],[Pontuação final]]<=12,"Leve", IF(Table1[[#This Row],[Pontuação final]]<=22,"Moderado", "Grave"))) -> Moderado
A17: 17 | B17: Masculino | C17: 19 | D17: 92 | E17: 1.8 | F17: Engenharia de Telecomunicações | G17: P3 | H17: Integral | I17: Monitoria ; | K17: Goiânia | L17: Goiás | M17: Familiares | O17: Sempre | P17: Frequentemente | Q17: 1 | R17: Frequentemente | S17: 1 | T17: Nunca / Raramente | U17: 0 | V17: Frequentemente | W17: 1 | X17: Nunca / Raramente | Y17: 0 | Z17: Nunca / Raramente | AA17: 0 | AB17: Frequentemente | AC17: 1 | AD17: Nunca / Raramente | AE17: 0 | AF17: Nunca / Raramente | AG17: 0 | AH17: Nunca / Raramente | AI17: 0 | AJ17: Nunca / Raramente | AK17: 0 | AL17: Frequentemente | AM17: 1 | AN17: Frequentemente | AO17: 1 | AP17: Nunca / Raramente | AQ17: 0 | AR17: Nunca / Raramente | AS17: 0 | AT17: Frequentemente | AU17: 1 | AV17: =SUM(Q17,S17,U17,W17,Y17,AA17,AC17,AE17,AG17,AI17,AK17,AM17,AO17,AQ17,AS17,AU17) -> 7 | AW17: =IF(Table1[[#This Row],[Pontuação final]]<=2,"Nenhum", IF(Table1[[#This Row],[Pontuação final]]<=12,"Leve", IF(Table1[[#This Row],[Pontuação final]]<=22,"Moderado", "Grave"))) -> Leve
A18: 18 | B18: Masculino | C18: 24 | D18: 105 | E18: 1.66 | F18: Engenharia de Software | G18: P7 | H18: Integral | I18: Estágio ; | K18: Passos | L18: Minas Gerais | M18: Familiares | O18: Nunca | P18: Sempre | Q18: 2 | R18: Nunca / Raramente | S18: 0 | T18: Sempre | U18: 2 | V18: Sempre | W18: 2 | X18: Frequentemente | Y18: 1 | Z18: Frequentemente | AA18: 1 | AB18: Frequentemente | AC18: 1 | AD18: Frequentemente | AE18: 1 | AF18: Frequentemente | AG18: 1 | AH18: Sempre | AI18: 2 | AJ18: Sempre | AK18: 2 | AL18: Sempre | AM18: 2 | AN18: Sempre | AO18: 2 | AP18: Frequentemente | AQ18: 1 | AR18: Sempre | AS18: 2 | AT18: Frequentemente | AU18: 1 | AV18: =SUM(Q18,S18,U18,W18,Y18,AA18,AC18,AE18,AG18,AI18,AK18,AM18,AO18,AQ18,AS18,AU18) -> 23 | AW18: =IF(Table1[[#This Row],[Pontuação final]]<=2,"Nenhum", IF(Table1[[#This Row],[Pontuação final]]<=12,"Leve", IF(Table1[[#This Row],[Pontuação final]]<=22,"Moderado", "Grave"))) -> Grave
A19: 19 | B19: Masculino | C19: 21 | D19: 64 | E19: 1.7 | F19: Engenharia de Software | G19: P3 | H19: Noturno | I19: Estágio ; | K19: Cambuí | L19: Minas Gerais | M19: Amigos/colegas | O19: Nunca | P19: Frequentemente | Q19: 1 | R19: Nunca / Raramente | S19: 0 | T19: Frequentemente | U19: 1 | V19: Frequentemente | W19: 1 | X19: Nunca / Raramente | Y19: 0 | Z19: Nunca / Raramente | AA19: 0 | AB19: Frequentemente | AC19: 1 | AD19: Frequentemente | AE19: 1 | AF19: Frequentemente | AG19: 1 | AH19: Sempre | AI19: 2 | AJ19: Sempre | AK19: 2 | AL19: Sempre | AM19: 2 | AN19: Nunca / Raramente | AO19: 0 | AP19: Nunca / Raramente | AQ19: 0 | AR19: Nunca / Raramente | AS19: 0 | AT19: Sempre | AU19: 2 | AV19: =SUM(Q19,S19,U19,W19,Y19,AA19,AC19,AE19,AG19,AI19,AK19,AM19,AO19,AQ19,AS19,AU19) -> 14 | AW19: =IF(Table1[[#This Row],[Pontuação final]]<=2,"Nenhum", IF(Table1[[#This Row],[Pontuação final]]<=12,"Leve", IF(Table1[[#This Row],[Pontuação final]]<=22,"Moderado", "Grave"))) -> Moderado
A20: 20 | B20: Feminino | C20: 22 | D20: 58 | E20: 1.69 | F20: Engenharia de Computação | G20: P10 | H20: Noturno | I20: Trabalho ; | K20: Pouso alegre | L20: Minas Gerais | M20: Familiares | O20: Sempre | P20: Sempre | Q20: 2 | R20: Sempre | S20: 2 | T20: Sempre | U20: 2 | V20: Frequentemente | W20: 1 | X20: Sempre | Y20: 2 | Z20: Sempre | AA20: 2 | AB20: Sempre | AC20: 2 | AD20: Sempre | AE20: 2 | AF20: Sempre | AG20: 2 | AH20: Frequentemente | AI20: 1 | AJ20: Nunca / Raramente | AK20: 0 | AL20: Sempre | AM20: 2 | AN20: Sempre | AO20: 2 | AP20: Nunca / Raramente | AQ20: 0 | AR20: Nunca / Raramente | AS20: 0 | AT20: Sempre | AU20: 2 | AV20: =SUM(Q20,S20,U20,W20,Y20,AA20,AC20,AE20,AG20,AI20,AK20,AM20,AO20,AQ20,AS20,AU20) -> 24 | AW20: =IF(Table1[[#This Row],[Pontuação final]]<=2,"Nenhum", IF(Table1[[#This Row],[Pontuação final]]<=12,"Leve", IF(Table1[[#This Row],[Pontuação final]]<=22,"Moderado", "Grave"))) -> Grave
A21: 21 | B21: Masculino | C21: 18 | D21: 55 | E21: 1.79 | F21: Engenharia de Computação | G21: P1 | H21: Noturno | I21: Outros; | K21: Santa Rita do Sapucaí | L21: Minas Gerais | M21: Sozinho | O21: Às vezes | P21: Sempre | Q21: 2 | R21: Nunca / Raramente | S21: 0 | T21: Nunca / Raramente | U21: 0 | V21: Frequentemente | W21: 1 | X21: Nunca / Raramente | Y21: 0 | Z21: Nunca / Raramente | AA21: 0 | AB21: Nunca / Raramente | AC21: 0 | AD21: Nunca / Raramente | AE21: 0 | AF21: Frequentemente | AG21: 1 | AH21: Frequentemente | AI21: 1 | AJ21: Nunca / Raramente | AK21: 0 | AL21: Frequentemente | AM21: 1 | AN21: Nunca / Raramente | AO21: 0 | AP21: Nunca / Raramente | AQ21: 0 | AR21: Nunca / Raramente | AS21: 0 | AT21: Frequentemente | AU21: 1 | AV21: =SUM(Q21,S21,U21,W21,Y21,AA21,AC21,AE21,AG21,AI21,AK21,AM21,AO21,AQ21,AS21,AU21) -> 7 | AW21: =IF(Table1[[#This Row],[Pontuação final]]<=2,"Nenhum", IF(Table1[[#This Row],[Pontuação final]]<=12,"Leve", IF(Table1[[#This Row],[Pontuação final]]<=22,"Moderado", "Grave"))) -> Leve
A22: 22 | B22: Masculino | C22: 22 | D22: 67 | E22: 1.75 | F22: Engenharia Elétrica | G22: P8 | H22: Noturno | I22: Trabalho ;Outros; | J22: Membro da ISA | K22: Volta Redonda | L22: Rio de Janeiro | M22: Amigos/colegas | O22: Às vezes | P22: Sempre | Q22: 2 | R22: Sempre | S22: 2 | T22: Nunca / Raramente | U22: 0 | V22: Sempre | W22: 2 | X22: Frequentemente | Y22: 1 | Z22: Nunca / Raramente | AA22: 0 | AB22: Frequentemente | AC22: 1 | AD22: Sempre | AE22: 2 | AF22: Frequentemente | AG22: 1 | AH22: Frequentemente | AI22: 1 | AJ22: Frequentemente | AK22: 1 | AL22: Sempre | AM22: 2 | AN22: Sempre | AO22: 2 | AP22: Sempre | AQ22: 2 | AR22: Sempre | AS22: 2 | AT22: Sempre | AU22: 2 | AV22: =SUM(Q22,S22,U22,W22,Y22,AA22,AC22,AE22,AG22,AI22,AK22,AM22,AO22,AQ22,AS22,AU22) -> 23 | AW22: =IF(Table1[[#This Row],[Pontuação final]]<=2,"Nenhum", IF(Table1[[#This Row],[Pontuação final]]<=12,"Leve", IF(Table1[[#This Row],[Pontuação final]]<=22,"Moderado", "Grave"))) -> Grave
A23: 23 | B23: Masculino | C23: 20 | D23: 86 | E23: 1.75 | F23: Engenharia de Software | G23: P7 | H23: Integral | I23: Iniciação Científica ; | K23: São Paulo | L23: São Paulo | M23: Familiares | O23: Sempre | P23: Sempre | Q23: 2 | R23: Nunca / Raramente | S23: 0 | T23: Nunca / Raramente | U23: 0 | V23: Sempre | W23: 2 | X23: Sempre | Y23: 2 | Z23: Nunca / Raramente | AA23: 0 | AB23: Nunca / Raramente | AC23: 0 | AD23: Nunca / Raramente | AE23: 0 | AF23: Sempre | AG23: 2 | AH23: Nunca / Raramente | AI23: 0 | AJ23: Nunca / Raramente | AK23: 0 | AL23: Sempre | AM23: 2 | AN23: Frequentemente | AO23: 1 | AP23: Nunca / Raramente | AQ23: 0 | AR23: Nunca / Raramente | AS23: 0 | AT23: Sempre | AU23: 2 | AV23: =SUM(Q23,S23,U23,W23,Y23,AA23,AC23,AE23,AG23,AI23,AK23,AM23,AO23,AQ23,AS23,AU23) -> 13 | AW23: =IF(Table1[[#This Row],[Pontuação final]]<=2,"Nenhum", IF(Table1[[#This Row],[Pontuação final]]<=12,"Leve", IF(Table1[[#This Row],[Pontuação final]]<=22,"Moderado", "Grave"))) -> Moderado
A24: 24 | B24: Masculino | C24: 24 | D24: 77 | E24: 1.78 | F24: Engenharia de Computação | G24: P9 | H24: Noturno | I24: Monitoria ; | K24: Volta Redonda | L24: Rio de Janeiro | M24: Amigos/colegas | O24: Às vezes | P24: Sempre | Q24: 2 | R24: Sempre | S24: 2 | T24: Sempre | U24: 2 | V24: Sempre | W24: 2 | X24: Frequentemente | Y24: 1 | Z24: Frequentemente | AA24: 1 | AB24: Frequentemente | AC24: 1 | AD24: Sempre | AE24: 2 | AF24: Frequentemente | AG24: 1 | AH24: Sempre | AI24: 2 | AJ24: Sempre | AK24: 2 | AL24: Sempre | AM24: 2 | AN24: Sempre | AO24: 2 | AP24: Frequentemente | AQ24: 1 | AR24: Frequentemente | AS24: 1 | AT24: Sempre | AU24: 2 | AV24: =SUM(Q24,S24,U24,W24,Y24,AA24,AC24,AE24,AG24,AI24,AK24,AM24,AO24,AQ24,AS24,AU24) -> 26 | AW24: =IF(Table1[[#This Row],[Pontuação final]]<=2,"Nenhum", IF(Table1[[#This Row],[Pontuação final]]<=12,"Leve", IF(Table1[[#This Row],[Pontuação final]]<=22,"Moderado", "Grave"))) -> Grave
A25: 25 | B25: Masculino | C25: 17 | D25: 57 | E25: 1.65 | F25: Engenharia de Computação | G25: P1 | H25: Integral | I25: Outros; | K25: Socorro | L25: São Paulo | M25: Sozinho | O25: Às vezes | P25: Sempre | Q25: 2 | R25: Sempre | S25: 2 | T25: Sempre | U25: 2 | V25: Sempre | W25: 2 | X25: Frequentemente | Y25: 1 | Z25: Nunca / Raramente | AA25: 0 | AB25: Nunca / Raramente | AC25: 0 | AD25: Frequentemente | AE25: 1 | AF25: Frequentemente | AG25: 1 | AH25: Nunca / Raramente | AI25: 0 | AJ25: Nunca / Raramente | AK25: 0 | AL25: Sempre | AM25: 2 | AN25: Frequentemente | AO25: 1 | AP25: Nunca / Raramente | AQ25: 0 | AR25: Frequentemente | AS25: 1 | AT25: Sempre | AU25: 2 | AV25: =SUM(Q25,S25,U25,W25,Y25,AA25,AC25,AE25,AG25,AI25,AK25,AM25,AO25,AQ25,AS25,AU25) -> 17 | AW25: =IF(Table1[[#This Row],[Pontuação final]]<=2,"Nenhum", IF(Table1[[#This Row],[Pontuação final]]<=12,"Leve", IF(Table1[[#This Row],[Pontuação final]]<=22,"Moderado", "Grave"))) -> Moderado
A26: 26 | B26: Masculino | C26: 20 | D26: 64 | E26: 1.69 | F26: Engenharia de Software | G26: P5 | H26: Integral | I26: Monitoria ; | K26: Pouso Alegre | L26: Minas Gerais | M26: Amigos/colegas | O26: Às vezes | P26: Sempre | Q26: 2 | R26: Sempre | S26: 2 | T26: Nunca / Raramente | U26: 0 | V26: Sempre | W26: 2 | X26: Frequentemente | Y26: 1 | Z26: Frequentemente | AA26: 1 | AB26: Frequentemente | AC26: 1 | AD26: Nunca / Raramente | AE26: 0 | AF26: Frequentemente | AG26: 1 | AH26: Frequentemente | AI26: 1 | AJ26: Nunca / Raramente | AK26: 0 | AL26: Sempre | AM26: 2 | AN26: Frequentemente | AO26: 1 | AP26: Nunca / Raramente | AQ26: 0 | AR26: Nunca / Raramente | AS26: 0 | AT26: Sempre | AU26: 2 | AV26: =SUM(Q26,S26,U26,W26,Y26,AA26,AC26,AE26,AG26,AI26,AK26,AM26,AO26,AQ26,AS26,AU26) -> 16 | AW26: =IF(Table1[[#This Row],[Pontuação final]]<=2,"Nenhum", IF(Table1[[#This Row],[Pontuação final]]<=12,"Leve", IF(Table1[[#This Row],[Pontuação final]]<=22,"Moderado", "Grave"))) -> Moderado
A27: 27 | B27: Masculino | C27: 19 | D27: 68 | E27: 1.75 | F27: Engenharia de Computação | G27: P4 | H27: Integral | I27: Monitoria ; | K27: Pouso Alegre | L27: Minas Gerais | M27: Familiares | O27: Sempre | P27: Sempre | Q27: 2 | R27: Sempre | S27: 2 | T27: Sempre | U27: 2 | V27: Sempre | W27: 2 | X27: Nunca / Raramente | Y27: 0 | Z27: Nunca / Raramente | AA27: 0 | AB27: Nunca / Raramente | AC27: 0 | AD27: Nunca / Raramente | AE27: 0 | AF27: Frequentemente | AG27: 1 | AH27: Frequentemente | AI27: 1 | AJ27: Nunca / Raramente | AK27: 0 | AL27: Sempre | AM27: 2 | AN27: Frequentemente | AO27: 1 | AP27: Nunca / Raramente | AQ27: 0 | AR27: Nunca / Raramente | AS27: 0 | AT27: Sempre | AU27: 2 | AV27: =SUM(Q27,S27,U27,W27,Y27,AA27,AC27,AE27,AG27,AI27,AK27,AM27,AO27,AQ27,AS27,AU27) -> 15 | AW27: =IF(Table1[[#This Row],[Pontuação final]]<=2,"Nenhum", IF(Table1[[#This Row],[Pontuação final]]<=12,"Leve", IF(Table1[[#This Row],[Pontuação final]]<=22,"Moderado", "Grave"))) -> Moderado
A28: 28 | B28: Masculino | C28: 19 | D28: 83 | E28: 1.81 | F28: Engenharia Biomédica | G28: P4 | H28: Noturno | I28: Outros; | J28: start | K28: Poços de Caldas | L28: Minas Gerais | M28: Outros | N28: pensão | O28: Às vezes | P28: Frequentemente | Q28: 1 | R28: Nunca / Raramente | S28: 0 | T28: Sempre | U28: 2 | V28: Sempre | W28: 2 | X28: Frequentemente | Y28: 1 | Z28: Nunca / Raramente | AA28: 0 | AB28: Frequentemente | AC28: 1 | AD28: Sempre | AE28: 2 | AF28: Sempre | AG28: 2 | AH28: Sempre | AI28: 2 | AJ28: Sempre | AK28: 2 | AL28: Sempre | AM28: 2 | AN28: Nunca / Raramente | AO28: 0 | AP28: Frequentemente | AQ28: 1 | AR28: Nunca / Raramente | AS28: 0 | AT28: Sempre | AU28: 2 | AV28: =SUM(Q28,S28,U28,W28,Y28,AA28,AC28,AE28,AG28,AI28,AK28,AM28,AO28,AQ28,AS28,AU28) -> 20 | AW28: =IF(Table1[[#This Row],[Pontuação final]]<=2,"Nenhum", IF(Table1[[#This Row],[Pontuação final]]<=12,"Leve", IF(Table1[[#This Row],[Pontuação final]]<=22,"Moderado", "Grave"))) -> Moderado
A29: 29 | B29: Feminino | C29: 30 | D29: 63 | E29: 1.57 | F29: Engenharia Biomédica | G29: P8 | H29: Noturno | I29: Iniciação Científica ; | K29: Santa Rita do Sapucaí | L29: Minas Gerais | M29: Outros | N29: Filha e esposo | O29: Nunca | P29: Sempre | Q29: 2 | R29: Nunca / Raramente | S29: 0 | T29: Sempre | U29: 2 | V29: Sempre | W29: 2 | X29: Frequentemente | Y29: 1 | Z29: Frequentemente | AA29: 1 | AB29: Nunca / Raramente | AC29: 0 | AD29: Sempre | AE29: 2 | AF29: Sempre | AG29: 2 | AH29: Sempre | AI29: 2 | AJ29: Sempre | AK29: 2 | AL29: Sempre | AM29: 2 | AN29: Frequentemente | AO29: 1 | AP29: Frequentemente | AQ29: 1 | AR29: Nunca / Raramente | AS29: 0 | AT29: Sempre | AU29: 2 | AV29: =SUM(Q29,S29,U29,W29,Y29,AA29,AC29,AE29,AG29,AI29,AK29,AM29,AO29,AQ29,AS29,AU29) -> 22 | AW29: =IF(Table1[[#This Row],[Pontuação final]]<=2,"Nenhum", IF(Table1[[#This Row],[Pontuação final]]<=12,"Leve", IF(Table1[[#This Row],[Pontuação final]]<=22,"Moderado", "Grave"))) -> Moderado
A30: 30 | B30: Masculino | C30: 20 | D30: 69 | E30: 1.75 | F30: Engenharia de Software | G30: P2 | H30: Noturno | I30: Estágio ; | K30: Pouso Alegre | L30: Minas Gerais | M30: Sozinho | O30: Sempre | P30: Frequentemente | Q30: 1 | R30: Nunca / Raramente | S30: 0 | T30: Frequentemente | U30: 1 | V30: Sempre | W30: 2 | X30: Nunca / Raramente | Y30: 0 | Z30: Nunca / Raramente | AA30: 0 | AB30: Nunca / Raramente | AC30: 0 | AD30: Frequentemente | AE30: 1 | AF30: Frequentemente | AG30: 1 | AH30: Sempre | AI30: 2 | AJ30: Sempre | AK30: 2 | AL30: Frequentemente | AM30: 1 | AN30: Nunca / Raramente | AO30: 0 | AP30: Nunca / Raramente | AQ30: 0 | AR30: Nunca / Raramente | AS30: 0 | AT30: Frequentemente | AU30: 1 | AV30: =SUM(Q30,S30,U30,W30,Y30,AA30,AC30,AE30,AG30,AI30,AK30,AM30,AO30,AQ30,AS30,AU30) -> 12 | AW30: =IF(Table1[[#This Row],[Pontuação final]]<=2,"Nenhum", IF(Table1[[#This Row],[Pontuação final]]<=12,"Leve", IF(Table1[[#This Row],[Pontuação final]]<=22,"Moderado", "Grave"))) -> Leve
A31: 31 | B31: Masculino | C31: 17 | D31: 70 | E31: 1.8 | F31: Engenharia de Computação | G31: P1 | H31: Integral | I31: Outros; | K31: Pedralva | L31: Minas Gerais | M31: Amigos/colegas | O31: Sempre | P31: Sempre | Q31: 2 | R31: Sempre | S31: 2 | T31: Frequentemente | U31: 1 | V31: Sempre | W31: 2 | X31: Nunca / Raramente | Y31: 0 | Z31: Sempre | AA31: 2 | AB31: Frequentemente | AC31: 1 | AD31: Nunca / Raramente | AE31: 0 | AF31: Sempre | AG31: 2 | AH31: Sempre | AI31: 2 | AJ31: Sempre | AK31: 2 | AL31: Sempre | AM31: 2 | AN31: Frequentemente | AO31: 1 | AP31: Frequentemente | AQ31: 1 | AR31: Nunca / Raramente | AS31: 0 | AT31: Sempre | AU31: 2 | AV31: =SUM(Q31,S31,U31,W31,Y31,AA31,AC31,AE31,AG31,AI31,AK31,AM31,AO31,AQ31,AS31,AU31) -> 22 | AW31: =IF(Table1[[#This Row],[Pontuação final]]<=2,"Nenhum", IF(Table1[[#This Row],[Pontuação final]]<=12,"Leve", IF(Table1[[#This Row],[Pontuação final]]<=22,"Moderado", "Grave"))) -> Moderado
A32: 32 | B32: Masculino | C32: 20 | D32: 56 | E32: 1.73 | F32: Engenharia de Software | G32: P6 | H32: Noturno | I32: Iniciação Científica ; | K32: Santa Rita do Sapucaí | L32: Minas Gerais | M32: Familiares | O32: Sempre | P32: Sempre | Q32: 2 | R32: Sempre | S32: 2 | T32: Sempre | U32: 2 | V32: Sempre | W32: 2 | X32: Nunca / Raramente | Y32: 0 | Z32: Frequentemente | AA32: 1 | AB32: Nunca / Raramente | AC32: 0 | AD32: Nunca / Raramente | AE32: 0 | AF32: Frequentemente | AG32: 1 | AH32: Sempre | AI32: 2 | AJ32: Sempre | AK32: 2 | AL32: Sempre | AM32: 2 | AN32: Frequentemente | AO32: 1 | AP32: Nunca / Raramente | AQ32: 0 | AR32: Nunca / Raramente | AS32: 0 | AT32: Sempre | AU32: 2 | AV32: =SUM(Q32,S32,U32,W32,Y32,AA32,AC32,AE32,AG32,AI32,AK32,AM32,AO32,AQ32,AS32,AU32) -> 19 | AW32: =IF(Table1[[#This Row],[Pontuação final]]<=2,"Nenhum", IF(Table1[[#This Row],[Pontuação final]]<=12,"Leve", IF(Table1[[#This Row],[Pontuação final]]<=22,"Moderado", "Grave"))) -> Moderado
A33: 33 | B33: Masculino | C33: 19 | D33: 65.5 | E33: 1.8 | F33: Engenharia de Computação | G33: P3 | H33: Integral | I33: Monitoria ; | K33: Caxambu | L33: Minas Gerais | M33: Sozinho | O33: Às vezes | P33: Sempre | Q33: 2 | R33: Sempre | S33: 2 | T33: Sempre | U33: 2 | V33: Sempre | W33: 2 | X33: Nunca / Raramente | Y33: 0 | Z33: Frequentemente | AA33: 1 | AB33: Nunca / Raramente | AC33: 0 | AD33: Frequentemente | AE33: 1 | AF33: Nunca / Raramente | AG33: 0 | AH33: Frequentemente | AI33: 1 | AJ33: Nunca / Raramente | AK33: 0 | AL33: Frequentemente | AM33: 1 | AN33: Frequentemente | AO33: 1 | AP33: Frequentemente | AQ33: 1 | AR33: Sempre | AS33: 2 | AT33: Frequentemente | AU33: 1 | AV33: =SUM(Q33,S33,U33,W33,Y33,AA33,AC33,AE33,AG33,AI33,AK33,AM33,AO33,AQ33,AS33,AU33) -> 17 | AW33: =IF(Table1[[#This Row],[Pontuação final]]<=2,"Nenhum", IF(Table1[[#This Row],[Pontuação final]]<=12,"Leve", IF(Table1[[#This Row],[Pontuação final]]<=22,"Moderado", "Grave"))) -> Moderado
A34: 34 | B34: Masculino | C34: 20 | D34: 70 | E34: 1.72 | F34: Engenharia de Software | G34: P5 | H34: Noturno | I34: Estágio ; | K34: São Lourenço | L34: Minas Gerais | M34: Sozinho | O34: Nunca | P34: Frequentemente | Q34: 1 | R34: Nunca / Raramente | S34: 0 | T34: Nunca / Raramente | U34: 0 | V34: Sempre | W34: 2 | X34: Frequentemente | Y34: 1 | Z34: Frequentemente | AA34: 1 | AB34: Frequentemente | AC34: 1 | AD34: Sempre | AE34: 2 | AF34: Sempre | AG34: 2 | AH34: Frequentemente | AI34: 1 | AJ34: Frequentemente | AK34: 1 | AL34: Sempre | AM34: 2 | AN34: Nunca / Raramente | AO34: 0 | AP34: Nunca / Raramente | AQ34: 0 | AR34: Nunca / Raramente | AS34: 0 | AT34: Frequentemente | AU34: 1 | AV34: =SUM(Q34,S34,U34,W34,Y34,AA34,AC34,AE34,AG34,AI34,AK34,AM34,AO34,AQ34,AS34,AU34) -> 15 | AW34: =IF(Table1[[#This Row],[Pontuação final]]<=2,"Nenhum", IF(Table1[[#This Row],[Pontuação final]]<=12,"Leve", IF(Table1[[#This Row],[Pontuação final]]<=22,"Moderado", "Grave"))) -> Moderado
A35: 35 | B35: Masculino | C35: 20 | D35: 79 | E35: 1.8 | F35: Engenharia de Telecomunicações | G35: P6 | H35: Integral | I35: Iniciação Científica ; | K35: Cruzília | L35: Minas Gerais | M35: Amigos/colegas | O35: Às vezes | P35: Sempre | Q35: 2 | R35: Nunca / Raramente | S35: 0 | T35: Nunca / Raramente | U35: 0 | V35: Sempre | W35: 2 | X35: Sempre | Y35: 2 | Z35: Frequentemente | AA35: 1 | AB35: Sempre | AC35: 2 | AD35: Sempre | AE35: 2 | AF35: Sempre | AG35: 2 | AH35: Frequentemente | AI35: 1 | AJ35: Sempre | AK35: 2 | AL35: Sempre | AM35: 2 | AN35: Frequentemente | AO35: 1 | AP35: Sempre | AQ35: 2 | AR35: Sempre | AS35: 2 | AT35: Sempre | AU35: 2 | AV35: =SUM(Q35,S35,U35,W35,Y35,AA35,AC35,AE35,AG35,AI35,AK35,AM35,AO35,AQ35,AS35,AU35) -> 25 | AW35: =IF(Table1[[#This Row],[Pontuação final]]<=2,"Nenhum", IF(Table1[[#This Row],[Pontuação final]]<=12,"Leve", IF(Table1[[#This Row],[Pontuação final]]<=22,"Moderado", "Grave"))) -> Grave
A36: 36 | B36: Feminino | C36: 24 | D36: 48 | E36: 1.53 | F36: Engenharia de Telecomunicações | G36: P8 | H36: Noturno | I36: Trabalho ; | K36: Santa Rita do Sapucaí | L36: Minas Gerais | M36: Familiares | O36: Às vezes | P36: Sempre | Q36: 2 | R36: Frequentemente | S36: 1 | T36: Nunca / Raramente | U36: 0 | V36: Sempre | W36: 2 | X36: Frequentemente | Y36: 1 | Z36: Frequentemente | AA36: 1 | AB36: Frequentemente | AC36: 1 | AD36: Nunca / Raramente | AE36: 0 | AF36: Frequentemente | AG36: 1 | AH36: Sempre | AI36: 2 | AJ36: Sempre | AK36: 2 | AL36: Sempre | AM36: 2 | AN36: Sempre | AO36: 2 | AP36: Frequentemente | AQ36: 1 | AR36: Frequentemente | AS36: 1 | AT36: Sempre | AU36: 2 | AV36: =SUM(Q36,S36,U36,W36,Y36,AA36,AC36,AE36,AG36,AI36,AK36,AM36,AO36,AQ36,AS36,AU36) -> 21 | AW36: =IF(Table1[[#This Row],[Pontuação final]]<=2,"Nenhum", IF(Table1[[#This Row],[Pontuação final]]<=12,"Leve", IF(Table1[[#This Row],[Pontuação final]]<=22,"Moderado", "Grave"))) -> Moderado
A37: 37 | B37: Masculino | C37: 21 | D37: 75 | E37: 1.78 | F37: Engenharia de Computação | G37: P7 | H37: Noturno | I37: Trabalho ; | K37: Santa Rita do Sapucaí | L37: Minas Gerais | M37: Familiares | O37: Às vezes | P37: Sempre | Q37: 2 | R37: Sempre | S37: 2 | T37: Frequentemente | U37: 1 | V37: Sempre | W37: 2 | X37: Nunca / Raramente | Y37: 0 | Z37: Nunca / Raramente | AA37: 0 | AB37: Nunca / Raramente | AC37: 0 | AD37: Nunca / Raramente | AE37: 0 | AF37: Frequentemente | AG37: 1 | AH37: Nunca / Raramente | AI37: 0 | AJ37: Nunca / Raramente | AK37: 0 | AL37: Sempre | AM37: 2 | AN37: Nunca / Raramente | AO37: 0 | AP37: Nunca / Raramente | AQ37: 0 | AR37: Nunca / Raramente | AS37: 0 | AT37: Frequentemente | AU37: 1 | AV37: =SUM(Q37,S37,U37,W37,Y37,AA37,AC37,AE37,AG37,AI37,AK37,AM37,AO37,AQ37,AS37,AU37) -> 11 | AW37: =IF(Table1[[#This Row],[Pontuação final]]<=2,"Nenhum", IF(Table1[[#This Row],[Pontuação final]]<=12,"Leve", IF(Table1[[#This Row],[Pontuação final]]<=22,"Moderado", "Grave"))) -> Leve
A38: 38 | B38: Feminino | C38: 22 | D38: 88 | E38: 1.75 | F38: Engenharia de Telecomunicações | G38: P5 | H38: Noturno | I38: Trabalho ; | K38: Santa Rita do Sapucaí | L38: Minas Gerais | M38: Familiares | O38: Sempre | P38: Sempre | Q38: 2 | R38: Nunca / Raramente | S38: 0 | T38: Frequentemente | U38: 1 | V38: Sempre | W38: 2 | X38: Frequentemente | Y38: 1 | Z38: Frequentemente | AA38: 1 | AB38: Frequentemente | AC38: 1 | AD38: Sempre | AE38: 2 | AF38: Sempre | AG38: 2 | AH38: Frequentemente | AI38: 1 | AJ38: Nunca / Raramente | AK38: 0 | AL38: Sempre | AM38: 2 | AN38: Sempre | AO38: 2 | AP38: Frequentemente | AQ38: 1 | AR38: Sempre | AS38: 2 | AT38: Sempre | AU38: 2 | AV38: =SUM(Q38,S38,U38,W38,Y38,AA38,AC38,AE38,AG38,AI38,AK38,AM38,AO38,AQ38,AS38,AU38) -> 22 | AW38: =IF(Table1[[#This Row],[Pontuação final]]<=2,"Nenhum", IF(Table1[[#This Row],[Pontuação final]]<=12,"Leve", IF(Table1[[#This Row],[Pontuação final]]<=22,"Moderado", "Grave"))) -> Moderado
A39: 39 | B39: Masculino | C39: 20 | D39: 79 | E39: 1.72 | F39: Engenharia de Software | G39: P5 | H39: Integral | I39: Monitoria ; | K39: Pouso Alegre | L39: Minas Gerais | M39: Amigos/colegas | O39: Às vezes | P39: Sempre | Q39: 2 | R39: Sempre | S39: 2 | T39: Nunca / Raramente | U39: 0 | V39: Frequentemente | W39: 1 | X39: Nunca / Raramente | Y39: 0 | Z39: Nunca / Raramente | AA39: 0 | AB39: Nunca / Raramente | AC39: 0 | AD39: Nunca / Raramente | AE39: 0 | AF39: Frequentemente | AG39: 1 | AH39: Nunca / Raramente | AI39: 0 | AJ39: Nunca / Raramente | AK39: 0 | AL39: Sempre | AM39: 2 | AN39: Frequentemente | AO39: 1 | AP39: Nunca / Raramente | AQ39: 0 | AR39: Nunca / Raramente | AS39: 0 | AT39: Frequentemente | AU39: 1 | AV39: =SUM(Q39,S39,U39,W39,Y39,AA39,AC39,AE39,AG39,AI39,AK39,AM39,AO39,AQ39,AS39,AU39) -> 10 | AW39: =IF(Table1[[#This Row],[Pontuação final]]<=2,"Nenhum", IF(Table1[[#This Row],[Pontuação final]]<=12,"Leve", IF(Table1[[#This Row],[Pontuação final]]<=22,"Moderado", "Grave"))) -> Leve
A40: 40 | B40: Masculino | C40: 22 | D40: 110 | E40: 1.86 | F40: Engenharia de Software | G40: P9 | H40: Integral | I40: Estágio ; | K40: Três Corações | L40: Minas Gerais | M40: Sozinho | O40: Às vezes | P40: Sempre | Q40: 2 | R40: Frequentemente | S40: 1 | T40: Nunca / Raramente | U40: 0 | V40: Sempre | W40: 2 | X40: Frequentemente | Y40: 1 | Z40: Frequentemente | AA40: 1 | AB40: Nunca / Raramente | AC40: 0 | AD40: Nunca / Raramente | AE40: 0 | AF40: Frequentemente | AG40: 1 | AH40: Sempre | AI40: 2 | AJ40: Sempre | AK40: 2 | AL40: Frequentemente | AM40: 1 | AN40: Frequentemente | AO40: 1 | AP40: Frequentemente | AQ40: 1 | AR40: Nunca / Raramente | AS40: 0 | AT40: Frequentemente | AU40: 1 | AV40: =SUM(Q40,S40,U40,W40,Y40,AA40,AC40,AE40,AG40,AI40,AK40,AM40,AO40,AQ40,AS40,AU40) -> 16 | AW40: =IF(Table1[[#This Row],[Pontuação final]]<=2,"Nenhum", IF(Table1[[#This Row],[Pontuação final]]<=12,"Leve", IF(Table1[[#This Row],[Pontuação final]]<=22,"Moderado", "Grave"))) -> Moderado
...

Sheet Mayara
B2: Tabela 1 - Análise da dependência em Smartfone de 224 alunos de uma faculdade de tecnologia do Sul de Minas Gerais no segundo semestre de 2022
B3: Curso | C3: fa | D3: fr
B4: Engenharia Biomédica | C4: =COUNTIF(Table1[Curso:],Mayara!B4) -> 19 | D4: =$C4/$C$11 -> 0.084821429
B5: Engenharia de Computação | C5: =COUNTIF(Table1[Curso:],Mayara!B5) -> 57 | D5: =$C5/$C$11 -> 0.25446429
B6: Engenharia de Controle e Automação | C6: =COUNTIF(Table1[Curso:],Mayara!B6) -> 15 | D6: =$C6/$C$11 -> 0.066964286
B7: Engenharia de Produção | C7: =COUNTIF(Table1[Curso:],Mayara!B7) -> 7 | D7: =$C7/$C$11 -> 0.03125
B8: Engenharia de Software | C8: =COUNTIF(Table1[Curso:],Mayara!B8) -> 88 | D8: =$C8/$C$11 -> 0.39285714
B9: Engenharia de Telecomunicações | C9: =COUNTIF(Table1[Curso:],Mayara!B9) -> 28 | D9: =$C9/$C$11 -> 0.125
B10: Engenharia Elétrica | C10: =COUNTIF(Table1[Curso:],Mayara!B10) -> 10 | D10: =$C10/$C$11 -> 0.044642857
B11: Total | C11: =SUM(C4:C10) -> 224 | D11: =SUM(D4:D10) -> 1
